Workbook

Sheet Assumptions
A1: TitleApp — Financial Model Assumptions
A2: The Title App LLC | March 2026
A3: Blue = editable input | Black = formula | Green = cross-sheet link
A5: RAISE & RUNWAY
A6: Gross Raise | B6: 1070000 | C6: Post-Money SAFE, $15M cap, 20% discount
A7: Wefunder Fees (%) | B7: 0.078
A8: Wefunder Fees ($) | B8: =B6*B7 -> 83460
A9: Legal & Filing Fees | B9: 18500
A10: Debt Repayment | B10: 165000
A11: Net Proceeds | B11: =B6-B8-B9-B10 -> 803040 | C11: Cash available for operations
A13: MONTHLY BURN RATE
A14: Engineering (2 FT) | B14: 12000
A15: AI/API Costs (Anthropic, OpenAI) | B15: 3000
A16: Infrastructure (Firebase, hosting) | B16: 2500
A17: Marketing & Growth | B17: 3000
A18: Legal & Compliance | B18: 1500
A19: Admin & Office | B19: 1800
A20: CEO/CFO (deferred/minimal) | B20: 4000
A21: Total Monthly Burn | B21: =SUM(B14:B20) -> 27800
A22: Zero-Revenue Runway (months) | B22: =ROUND(B11/B21,0) -> 29
A24: REVENUE ASSUMPTIONS — WORKER SUBSCRIPTIONS
A25: Avg Worker Price ($/mo) | B25: 65 | C25: Blended across $29-$99 range
A26: Annual Discount | B26: 0.2
A27: Annual Subscriber Mix | B27: 0.3
A28: Effective Avg Price ($/mo) | B28: =B25*(1-B26*B27) -> 61.1
A29: Monthly Churn Rate | B29: 0.05
A31: Workers per Subscriber (avg) | B31: 2.5 | C31: Grows as cross-worker value proven
A32: Avg Revenue per Account ($/mo) | B32: =B28*B31 -> 152.75
A34: REVENUE ASSUMPTIONS — OTHER STREAMS
A35: Creator Marketplace Take Rate | B35: 0.25
A36: Token/Usage Revenue per Sub ($/mo) | B36: 8
A37: Creator License Fee ($/yr) | B37: 49
A39: GROWTH SCENARIOS — MONTHLY NEW SUBSCRIBERS
B40: M1-3 | C40: M4-6 | D40: M7-9 | E40: M10-12 | F40: M13-18 | G40: M19-24 | H40: M25-36
A41: No Revenue | B41: 0 | C41: 0 | D41: 0 | E41: 0 | F41: 0 | G41: 0 | H41: 0
A42: Base Case | B42: 5 | C42: 10 | D42: 20 | E42: 35 | F42: 50 | G42: 75 | H42: 100 | I42: New subs/month in each period
A43: Best Case | B43: 10 | C43: 25 | D43: 50 | E43: 80 | F43: 120 | G43: 175 | H43: 250
A45: BURN RATE GROWTH
A46: Burn Increase per Quarter | B46: 0.05 | C46: Team growth, infra scaling
A48: WORKER CATALOG
...

Sheet No Revenue
A1: TitleApp — 36-Month Projection: No Revenue
A2: All figures in USD
B4: M1 | C4: M2 | D4: M3 | E4: M4 | F4: M5 | G4: M6 | H4: M7 | I4: M8 | J4: M9 | K4: M10 | L4: M11 | M4: M12 | N4: M13 | O4: M14 | P4: M15 | Q4: M16 | R4: M17 | S4: M18 | T4: M19 | U4: M20 | V4: M21 | W4: M22 | X4: M23 | Y4: M24 | Z4: M25 | AA4: M26 | AB4: M27 | AC4: M28 | AD4: M29 | AE4: M30 | AF4: M31 | AG4: M32 | AH4: M33 | AI4: M34 | AJ4: M35 | AK4: M36
A5: SUBSCRIBERS
A6: New Subscribers | B6: 0 | C6: 0 | D6: 0 | E6: 0 | F6: 0 | G6: 0 | H6: 0 | I6: 0 | J6: 0 | K6: 0 | L6: 0 | M6: 0 | N6: 0 | O6: 0 | P6: 0 | Q6: 0 | R6: 0 | S6: 0 | T6: 0 | U6: 0 | V6: 0 | W6: 0 | X6: 0 | Y6: 0 | Z6: 0 | AA6: 0 | AB6: 0 | AC6: 0 | AD6: 0 | AE6: 0 | AF6: 0 | AG6: 0 | AH6: 0 | AI6: 0 | AJ6: 0 | AK6: 0
A7: Churned Subscribers | B7: 0 | C7: =-ROUND(B9*Assumptions!$B$29,0) -> 0 | D7: =-ROUND(C9*Assumptions!$B$29,0) -> 0 | E7: =-ROUND(D9*Assumptions!$B$29,0) -> 0 | F7: =-ROUND(E9*Assumptions!$B$29,0) -> 0 | G7: =-ROUND(F9*Assumptions!$B$29,0) -> 0 | H7: =-ROUND(G9*Assumptions!$B$29,0) -> 0 | I7: =-ROUND(H9*Assumptions!$B$29,0) -> 0 | J7: =-ROUND(I9*Assumptions!$B$29,0) -> 0 | ... AK7: =-ROUND(AJ9*Assumptions!$B$29,0) -> 0
A8: Net New Subscribers | B8: =B6+B7 -> 0 | C8: =C6+C7 -> 0 | D8: =D6+D7 -> 0 | E8: =E6+E7 -> 0 | F8: =F6+F7 -> 0 | G8: =G6+G7 -> 0 | H8: =H6+H7 -> 0 | I8: =I6+I7 -> 0 | ... AK8: =AK6+AK7 -> 0
A9: Cumulative Subscribers | B9: =B8 -> 0 | C9: =B9+C8 -> 0 | D9: =C9+D8 -> 0 | E9: =D9+E8 -> 0 | F9: =E9+F8 -> 0 | G9: =F9+G8 -> 0 | H9: =G9+H8 -> 0 | I9: =H9+I8 -> 0 | J9: =I9+J8 -> 0 | ... AK9: =AJ9+AK8 -> 0
A11: REVENUE
A12: Subscription Revenue | B12: =B9*Assumptions!$B$32 -> 0 | C12: =C9*Assumptions!$B$32 -> 0 | D12: =D9*Assumptions!$B$32 -> 0 | E12: =E9*Assumptions!$B$32 -> 0 | F12: =F9*Assumptions!$B$32 -> 0 | G12: =G9*Assumptions!$B$32 -> 0 | H12: =H9*Assumptions!$B$32 -> 0 | I12: =I9*Assumptions!$B$32 -> 0 | ... AK12: =AK9*Assumptions!$B$32 -> 0
A13: Token/Usage Revenue | B13: =B9*Assumptions!$B$36 -> 0 | C13: =C9*Assumptions!$B$36 -> 0 | D13: =D9*Assumptions!$B$36 -> 0 | E13: =E9*Assumptions!$B$36 -> 0 | F13: =F9*Assumptions!$B$36 -> 0 | G13: =G9*Assumptions!$B$36 -> 0 | H13: =H9*Assumptions!$B$36 -> 0 | I13: =I9*Assumptions!$B$36 -> 0 | ... AK13: =AK9*Assumptions!$B$36 -> 0
A14: Creator Licenses | B14: =ROUND(B9*0.1,0)*Assumptions!$B$37/12 -> 0 | C14: =ROUND(C9*0.1,0)*Assumptions!$B$37/12 -> 0 | D14: =ROUND(D9*0.1,0)*Assumptions!$B$37/12 -> 0 | E14: =ROUND(E9*0.1,0)*Assumptions!$B$37/12 -> 0 | F14: =ROUND(F9*0.1,0)*Assumptions!$B$37/12 -> 0 | G14: =ROUND(G9*0.1,0)*Assumptions!$B$37/12 -> 0 | H14: =ROUND(H9*0.1,0)*Assumptions!$B$37/12 -> 0 | I14: =ROUND(I9*0.1,0)*Assumptions!$B$37/12 -> 0 | ... AK14: =ROUND(AK9*0.1,0)*Assumptions!$B$37/12 -> 0
A15: Total Monthly Revenue | B15: =B12+B13+B14 -> 0 | C15: =C12+C13+C14 -> 0 | D15: =D12+D13+D14 -> 0 | E15: =E12+E13+E14 -> 0 | F15: =F12+F13+F14 -> 0 | G15: =G12+G13+G14 -> 0 | H15: =H12+H13+H14 -> 0 | I15: =I12+I13+I14 -> 0 | ... AK15: =AK12+AK13+AK14 -> 0
A17: EXPENSES
A18: Monthly Burn (with growth) | B18: =Assumptions!$B$21*(1+Assumptions!$B$46)^0 -> 27800 | C18: =Assumptions!$B$21*(1+Assumptions!$B$46)^0 -> 27800 | D18: =Assumptions!$B$21*(1+Assumptions!$B$46)^0 -> 27800 | E18: =Assumptions!$B$21*(1+Assumptions!$B$46)^1 -> 29190 | F18: =Assumptions!$B$21*(1+Assumptions!$B$46)^1 -> 29190 | G18: =Assumptions!$B$21*(1+Assumptions!$B$46)^1 -> 29190 | H18: =Assumptions!$B$21*(1+Assumptions!$B$46)^2 -> 30649.5 | I18: =Assumptions!$B$21*(1+Assumptions!$B$46)^2 -> 30649.5 | J18: =Assumptions!$B$21*(1+Assumptions!$B$46)^2 -> 30649.5 | K18: =Assumptions!$B$21*(1+Assumptions!$B$46)^3 -> 32181.975 | L18: =Assumptions!$B$21*(1+Assumptions!$B$46)^3 -> 32181.975 | M18: =Assumptions!$B$21*(1+Assumptions!$B$46)^3 -> 32181.975 | N18: =Assumptions!$B$21*(1+Assumptions!$B$46)^4 -> 33791.074 | O18: =Assumptions!$B$21*(1+Assumptions!$B$46)^4 -> 33791.074 | P18: =Assumptions!$B$21*(1+Assumptions!$B$46)^4 -> 33791.074 | Q18: =Assumptions!$B$21*(1+Assumptions!$B$46)^5 -> 35480.627 | R18: =Assumptions!$B$21*(1+Assumptions!$B$46)^5 -> 35480.627 | S18: =Assumptions!$B$21*(1+Assumptions!$B$46)^5 -> 35480.627 | T18: =Assumptions!$B$21*(1+Assumptions!$B$46)^6 -> 37254.659 | U18: =Assumptions!$B$21*(1+Assumptions!$B$46)^6 -> 37254.659 | V18: =Assumptions!$B$21*(1+Assumptions!$B$46)^6 -> 37254.659 | W18: =Assumptions!$B$21*(1+Assumptions!$B$46)^7 -> 39117.392 | X18: =Assumptions!$B$21*(1+Assumptions!$B$46)^7 -> 39117.392 | Y18: =Assumptions!$B$21*(1+Assumptions!$B$46)^7 -> 39117.392 | Z18: =Assumptions!$B$21*(1+Assumptions!$B$46)^8 -> 41073.261 | AA18: =Assumptions!$B$21*(1+Assumptions!$B$46)^8 -> 41073.261 | AB18: =Assumptions!$B$21*(1+Assumptions!$B$46)^8 -> 41073.261 | AC18: =Assumptions!$B$21*(1+Assumptions!$B$46)^9 -> 43126.924 | AD18: =Assumptions!$B$21*(1+Assumptions!$B$46)^9 -> 43126.924 | AE18: =Assumptions!$B$21*(1+Assumptions!$B$46)^9 -> 43126.924 | AF18: =Assumptions!$B$21*(1+Assumptions!$B$46)^10 -> 45283.271 | AG18: =Assumptions!$B$21*(1+Assumptions!$B$46)^10 -> 45283.271 | AH18: =Assumptions!$B$21*(1+Assumptions!$B$46)^10 -> 45283.271 | AI18: =Assumptions!$B$21*(1+Assumptions!$B$46)^11 -> 47547.434 | AJ18: =Assumptions!$B$21*(1+Assumptions!$B$46)^11 -> 47547.434 | AK18: =Assumptions!$B$21*(1+Assumptions!$B$46)^11 -> 47547.434
A19: Variable AI Costs (per sub) | B19: =MAX(0,B9*5-Assumptions!$B$15) -> 0 | C19: =MAX(0,C9*5-Assumptions!$B$15) -> 0 | D19: =MAX(0,D9*5-Assumptions!$B$15) -> 0 | E19: =MAX(0,E9*5-Assumptions!$B$15) -> 0 | F19: =MAX(0,F9*5-Assumptions!$B$15) -> 0 | G19: =MAX(0,G9*5-Assumptions!$B$15) -> 0 | H19: =MAX(0,H9*5-Assumptions!$B$15) -> 0 | I19: =MAX(0,I9*5-Assumptions!$B$15) -> 0 | ... AK19: =MAX(0,AK9*5-Assumptions!$B$15) -> 0
A20: Total Monthly Expenses | B20: =B18+B19 -> 27800 | C20: =C18+C19 -> 27800 | D20: =D18+D19 -> 27800 | E20: =E18+E19 -> 29190 | F20: =F18+F19 -> 29190 | G20: =G18+G19 -> 29190 | H20: =H18+H19 -> 30649.5 | I20: =I18+I19 -> 30649.5 | ... AK20: =AK18+AK19 -> 47547.434
A22: CASH POSITION
A23: Monthly Net Income | B23: =B15-B20 -> -27800 | C23: =C15-C20 -> -27800 | D23: =D15-D20 -> -27800 | E23: =E15-E20 -> -29190 | F23: =F15-F20 -> -29190 | G23: =G15-G20 -> -29190 | H23: =H15-H20 -> -30649.5 | I23: =I15-I20 -> -30649.5 | ... AK23: =AK15-AK20 -> -47547.434
A24: Cash Balance | B24: =Assumptions!$B$11+B23 -> 775240 | C24: =B24+C23 -> 747440 | D24: =C24+D23 -> 719640 | E24: =D24+E23 -> 690450 | F24: =E24+F23 -> 661260 | G24: =F24+G23 -> 632070 | H24: =G24+H23 -> 601420.5 | I24: =H24+I23 -> 570771 | J24: =I24+J23 -> 540121.5 | ... AK24: =AJ24+AK23 -> -524448.35
A25: Cash Positive? | B25: =IF(B23>0,"YES","NO") -> NO | C25: =IF(C23>0,"YES","NO") -> NO | D25: =IF(D23>0,"YES","NO") -> NO | E25: =IF(E23>0,"YES","NO") -> NO | F25: =IF(F23>0,"YES","NO") -> NO | G25: =IF(G23>0,"YES","NO") -> NO | H25: =IF(H23>0,"YES","NO") -> NO | I25: =IF(I23>0,"YES","NO") -> NO | ... AK25: =IF(AK23>0,"YES","NO") -> NO
A27: KEY METRICS
A28: Monthly Recurring Revenue | B28: =B12 -> 0 | C28: =C12 -> 0 | D28: =D12 -> 0 | E28: =E12 -> 0 | F28: =F12 -> 0 | G28: =G12 -> 0 | H28: =H12 -> 0 | I28: =I12 -> 0 | ... AK28: =AK12 -> 0
A29: Annualized Revenue (ARR) | B29: =B15*12 -> 0 | C29: =C15*12 -> 0 | D29: =D15*12 -> 0 | E29: =E15*12 -> 0 | F29: =F15*12 -> 0 | G29: =G15*12 -> 0 | H29: =H15*12 -> 0 | I29: =I15*12 -> 0 | ... AK29: =AK15*12 -> 0
A30: Burn Multiple | B30: =IF(B15=0,"-",B20/B15) -> - | C30: =IF(C15=0,"-",C20/C15) -> - | D30: =IF(D15=0,"-",D20/D15) -> - | E30: =IF(E15=0,"-",E20/E15) -> - | F30: =IF(F15=0,"-",F20/F15) -> - | G30: =IF(G15=0,"-",G20/G15) -> - | H30: =IF(H15=0,"-",H20/H15) -> - | I30: =IF(I15=0,"-",I20/I15) -> - | ... AK30: =IF(AK15=0,"-",AK20/AK15) -> -
A31: Months of Cash Remaining | B31: =IF(B23>=0,"∞",B24/(-B23)) -> 27.886331 | C31: =IF(C23>=0,"∞",C24/(-C23)) -> 26.886331 | D31: =IF(D23>=0,"∞",D24/(-D23)) -> 25.886331 | E31: =IF(E23>=0,"∞",E24/(-E23)) -> 23.653649 | F31: =IF(F23>=0,"∞",F24/(-F23)) -> 22.653649 | G31: =IF(G23>=0,"∞",G24/(-G23)) -> 21.653649 | H31: =IF(H23>=0,"∞",H24/(-H23)) -> 19.622522 | I31: =IF(I23>=0,"∞",I24/(-I23)) -> 18.622522 | ... AK31: =IF(AK23>=0,"∞",AK24/(-AK23)) -> -11.030003

Sheet Base Case
A1: TitleApp — 36-Month Projection: Base Case
A2: All figures in USD
B4: M1 | C4: M2 | D4: M3 | E4: M4 | F4: M5 | G4: M6 | H4: M7 | I4: M8 | J4: M9 | K4: M10 | L4: M11 | M4: M12 | N4: M13 | O4: M14 | P4: M15 | Q4: M16 | R4: M17 | S4: M18 | T4: M19 | U4: M20 | V4: M21 | W4: M22 | X4: M23 | Y4: M24 | Z4: M25 | AA4: M26 | AB4: M27 | AC4: M28 | AD4: M29 | AE4: M30 | AF4: M31 | AG4: M32 | AH4: M33 | AI4: M34 | AJ4: M35 | AK4: M36
A5: SUBSCRIBERS
A6: New Subscribers | B6: 5 | C6: 5 | D6: 5 | E6: 10 | F6: 10 | G6: 10 | H6: 20 | I6: 20 | J6: 20 | K6: 35 | L6: 35 | M6: 35 | N6: 50 | O6: 50 | P6: 50 | Q6: 50 | R6: 50 | S6: 50 | T6: 75 | U6: 75 | V6: 75 | W6: 75 | X6: 75 | Y6: 75 | Z6: 100 | AA6: 100 | AB6: 100 | AC6: 100 | AD6: 100 | AE6: 100 | AF6: 100 | AG6: 100 | AH6: 100 | AI6: 100 | AJ6: 100 | AK6: 100
A7: Churned Subscribers | B7: 0 | C7: =-ROUND(B9*Assumptions!$B$29,0) -> 0 | D7: =-ROUND(C9*Assumptions!$B$29,0) -> -1 | E7: =-ROUND(D9*Assumptions!$B$29,0) -> -1 | F7: =-ROUND(E9*Assumptions!$B$29,0) -> -1 | G7: =-ROUND(F9*Assumptions!$B$29,0) -> -2 | H7: =-ROUND(G9*Assumptions!$B$29,0) -> -2 | I7: =-ROUND(H9*Assumptions!$B$29,0) -> -3 | J7: =-ROUND(I9*Assumptions!$B$29,0) -> -4 | ... AK7: =-ROUND(AJ9*Assumptions!$B$29,0) -> -63
A8: Net New Subscribers | B8: =B6+B7 -> 5 | C8: =C6+C7 -> 5 | D8: =D6+D7 -> 4 | E8: =E6+E7 -> 9 | F8: =F6+F7 -> 9 | G8: =G6+G7 -> 8 | H8: =H6+H7 -> 18 | I8: =I6+I7 -> 17 | ... AK8: =AK6+AK7 -> 37
A9: Cumulative Subscribers | B9: =B8 -> 5 | C9: =B9+C8 -> 10 | D9: =C9+D8 -> 14 | E9: =D9+E8 -> 23 | F9: =E9+F8 -> 32 | G9: =F9+G8 -> 40 | H9: =G9+H8 -> 58 | I9: =H9+I8 -> 75 | J9: =I9+J8 -> 91 | ... AK9: =AJ9+AK8 -> 1289
A11: REVENUE
A12: Subscription Revenue | B12: =B9*Assumptions!$B$32 -> 763.75 | C12: =C9*Assumptions!$B$32 -> 1527.5 | D12: =D9*Assumptions!$B$32 -> 2138.5 | E12: =E9*Assumptions!$B$32 -> 3513.25 | F12: =F9*Assumptions!$B$32 -> 4888 | G12: =G9*Assumptions!$B$32 -> 6110 | H12: =H9*Assumptions!$B$32 -> 8859.5 | I12: =I9*Assumptions!$B$32 -> 11456.25 | ... AK12: =AK9*Assumptions!$B$32 -> 196894.75
A13: Token/Usage Revenue | B13: =B9*Assumptions!$B$36 -> 40 | C13: =C9*Assumptions!$B$36 -> 80 | D13: =D9*Assumptions!$B$36 -> 112 | E13: =E9*Assumptions!$B$36 -> 184 | F13: =F9*Assumptions!$B$36 -> 256 | G13: =G9*Assumptions!$B$36 -> 320 | H13: =H9*Assumptions!$B$36 -> 464 | I13: =I9*Assumptions!$B$36 -> 600 | ... AK13: =AK9*Assumptions!$B$36 -> 10312
A14: Creator Licenses | B14: =ROUND(B9*0.1,0)*Assumptions!$B$37/12 -> 4.0833333 | C14: =ROUND(C9*0.1,0)*Assumptions!$B$37/12 -> 4.0833333 | D14: =ROUND(D9*0.1,0)*Assumptions!$B$37/12 -> 4.0833333 | E14: =ROUND(E9*0.1,0)*Assumptions!$B$37/12 -> 8.1666667 | F14: =ROUND(F9*0.1,0)*Assumptions!$B$37/12 -> 12.25 | G14: =ROUND(G9*0.1,0)*Assumptions!$B$37/12 -> 16.333333 | H14: =ROUND(H9*0.1,0)*Assumptions!$B$37/12 -> 24.5 | I14: =ROUND(I9*0.1,0)*Assumptions!$B$37/12 -> 32.666667 | ... AK14: =ROUND(AK9*0.1,0)*Assumptions!$B$37/12 -> 526.75
A15: Total Monthly Revenue | B15: =B12+B13+B14 -> 807.83333 | C15: =C12+C13+C14 -> 1611.5833 | D15: =D12+D13+D14 -> 2254.5833 | E15: =E12+E13+E14 -> 3705.4167 | F15: =F12+F13+F14 -> 5156.25 | G15: =G12+G13+G14 -> 6446.3333 | H15: =H12+H13+H14 -> 9348 | I15: =I12+I13+I14 -> 12088.917 | ... AK15: =AK12+AK13+AK14 -> 207733.5
A17: EXPENSES
A18: Monthly Burn (with growth) | B18: =Assumptions!$B$21*(1+Assumptions!$B$46)^0 -> 27800 | C18: =Assumptions!$B$21*(1+Assumptions!$B$46)^0 -> 27800 | D18: =Assumptions!$B$21*(1+Assumptions!$B$46)^0 -> 27800 | E18: =Assumptions!$B$21*(1+Assumptions!$B$46)^1 -> 29190 | F18: =Assumptions!$B$21*(1+Assumptions!$B$46)^1 -> 29190 | G18: =Assumptions!$B$21*(1+Assumptions!$B$46)^1 -> 29190 | H18: =Assumptions!$B$21*(1+Assumptions!$B$46)^2 -> 30649.5 | I18: =Assumptions!$B$21*(1+Assumptions!$B$46)^2 -> 30649.5 | J18: =Assumptions!$B$21*(1+Assumptions!$B$46)^2 -> 30649.5 | K18: =Assumptions!$B$21*(1+Assumptions!$B$46)^3 -> 32181.975 | L18: =Assumptions!$B$21*(1+Assumptions!$B$46)^3 -> 32181.975 | M18: =Assumptions!$B$21*(1+Assumptions!$B$46)^3 -> 32181.975 | N18: =Assumptions!$B$21*(1+Assumptions!$B$46)^4 -> 33791.074 | O18: =Assumptions!$B$21*(1+Assumptions!$B$46)^4 -> 33791.074 | P18: =Assumptions!$B$21*(1+Assumptions!$B$46)^4 -> 33791.074 | Q18: =Assumptions!$B$21*(1+Assumptions!$B$46)^5 -> 35480.627 | R18: =Assumptions!$B$21*(1+Assumptions!$B$46)^5 -> 35480.627 | S18: =Assumptions!$B$21*(1+Assumptions!$B$46)^5 -> 35480.627 | T18: =Assumptions!$B$21*(1+Assumptions!$B$46)^6 -> 37254.659 | U18: =Assumptions!$B$21*(1+Assumptions!$B$46)^6 -> 37254.659 | V18: =Assumptions!$B$21*(1+Assumptions!$B$46)^6 -> 37254.659 | W18: =Assumptions!$B$21*(1+Assumptions!$B$46)^7 -> 39117.392 | X18: =Assumptions!$B$21*(1+Assumptions!$B$46)^7 -> 39117.392 | Y18: =Assumptions!$B$21*(1+Assumptions!$B$46)^7 -> 39117.392 | Z18: =Assumptions!$B$21*(1+Assumptions!$B$46)^8 -> 41073.261 | AA18: =Assumptions!$B$21*(1+Assumptions!$B$46)^8 -> 41073.261 | AB18: =Assumptions!$B$21*(1+Assumptions!$B$46)^8 -> 41073.261 | AC18: =Assumptions!$B$21*(1+Assumptions!$B$46)^9 -> 43126.924 | AD18: =Assumptions!$B$21*(1+Assumptions!$B$46)^9 -> 43126.924 | AE18: =Assumptions!$B$21*(1+Assumptions!$B$46)^9 -> 43126.924 | AF18: =Assumptions!$B$21*(1+Assumptions!$B$46)^10 -> 45283.271 | AG18: =Assumptions!$B$21*(1+Assumptions!$B$46)^10 -> 45283.271 | AH18: =Assumptions!$B$21*(1+Assumptions!$B$46)^10 -> 45283.271 | AI18: =Assumptions!$B$21*(1+Assumptions!$B$46)^11 -> 47547.434 | AJ18: =Assumptions!$B$21*(1+Assumptions!$B$46)^11 -> 47547.434 | AK18: =Assumptions!$B$21*(1+Assumptions!$B$46)^11 -> 47547.434
A19: Variable AI Costs (per sub) | B19: =MAX(0,B9*5-Assumptions!$B$15) -> 0 | C19: =MAX(0,C9*5-Assumptions!$B$15) -> 0 | D19: =MAX(0,D9*5-Assumptions!$B$15) -> 0 | E19: =MAX(0,E9*5-Assumptions!$B$15) -> 0 | F19: =MAX(0,F9*5-Assumptions!$B$15) -> 0 | G19: =MAX(0,G9*5-Assumptions!$B$15) -> 0 | H19: =MAX(0,H9*5-Assumptions!$B$15) -> 0 | I19: =MAX(0,I9*5-Assumptions!$B$15) -> 0 | ... AK19: =MAX(0,AK9*5-Assumptions!$B$15) -> 3445
A20: Total Monthly Expenses | B20: =B18+B19 -> 27800 | C20: =C18+C19 -> 27800 | D20: =D18+D19 -> 27800 | E20: =E18+E19 -> 29190 | F20: =F18+F19 -> 29190 | G20: =G18+G19 -> 29190 | H20: =H18+H19 -> 30649.5 | I20: =I18+I19 -> 30649.5 | ... AK20: =AK18+AK19 -> 50992.434
A22: CASH POSITION
A23: Monthly Net Income | B23: =B15-B20 -> -26992.167 | C23: =C15-C20 -> -26188.417 | D23: =D15-D20 -> -25545.417 | E23: =E15-E20 -> -25484.583 | F23: =F15-F20 -> -24033.75 | G23: =G15-G20 -> -22743.667 | H23: =H15-H20 -> -21301.5 | I23: =I15-I20 -> -18560.583 | ... AK23: =AK15-AK20 -> 156741.07
A24: Cash Balance | B24: =Assumptions!$B$11+B23 -> 776047.83 | C24: =B24+C23 -> 749859.42 | D24: =C24+D23 -> 724314 | E24: =D24+E23 -> 698829.42 | F24: =E24+F23 -> 674795.67 | G24: =F24+G23 -> 652052 | H24: =G24+H23 -> 630750.5 | I24: =H24+I23 -> 612189.92 | J24: =I24+J23 -> 596205.42 | ... AK24: =AJ24+AK23 -> 2447584.9
A25: Cash Positive? | B25: =IF(B23>0,"YES","NO") -> NO | C25: =IF(C23>0,"YES","NO") -> NO | D25: =IF(D23>0,"YES","NO") -> NO | E25: =IF(E23>0,"YES","NO") -> NO | F25: =IF(F23>0,"YES","NO") -> NO | G25: =IF(G23>0,"YES","NO") -> NO | H25: =IF(H23>0,"YES","NO") -> NO | I25: =IF(I23>0,"YES","NO") -> NO | ... AK25: =IF(AK23>0,"YES","NO") -> YES
A27: KEY METRICS
A28: Monthly Recurring Revenue | B28: =B12 -> 763.75 | C28: =C12 -> 1527.5 | D28: =D12 -> 2138.5 | E28: =E12 -> 3513.25 | F28: =F12 -> 4888 | G28: =G12 -> 6110 | H28: =H12 -> 8859.5 | I28: =I12 -> 11456.25 | ... AK28: =AK12 -> 196894.75
A29: Annualized Revenue (ARR) | B29: =B15*12 -> 9694 | C29: =C15*12 -> 19339 | D29: =D15*12 -> 27055 | E29: =E15*12 -> 44465 | F29: =F15*12 -> 61875 | G29: =G15*12 -> 77356 | H29: =H15*12 -> 112176 | I29: =I15*12 -> 145067 | ... AK29: =AK15*12 -> 2492802
A30: Burn Multiple | B30: =IF(B15=0,"-",B20/B15) -> 34.413039 | C30: =IF(C15=0,"-",C20/C15) -> 17.250116 | D30: =IF(D15=0,"-",D20/D15) -> 12.330438 | E30: =IF(E15=0,"-",E20/E15) -> 7.8776566 | F30: =IF(F15=0,"-",F20/F15) -> 5.6610909 | G30: =IF(G15=0,"-",G20/G15) -> 4.5281555 | H30: =IF(H15=0,"-",H20/H15) -> 3.2787227 | I30: =IF(I15=0,"-",I20/I15) -> 2.5353388 | ... AK30: =IF(AK15=0,"-",AK20/AK15) -> 0.24547044
A31: Months of Cash Remaining | B31: =IF(B23>=0,"∞",B24/(-B23)) -> 28.750854 | C31: =IF(C23>=0,"∞",C24/(-C23)) -> 28.633248 | D31: =IF(D23>=0,"∞",D24/(-D23)) -> 28.353971 | E31: =IF(E23>=0,"∞",E24/(-E23)) -> 27.421654 | F31: =IF(F23>=0,"∞",F24/(-F23)) -> 28.077003 | G31: =IF(G23>=0,"∞",G24/(-G23)) -> 28.669608 | H31: =IF(H23>=0,"∞",H24/(-H23)) -> 29.610614 | I31: =IF(I23>=0,"∞",I24/(-I23)) -> 32.983334 | ... AK31: =IF(AK23>=0,"∞",AK24/(-AK23)) -> ∞

Sheet Best Case
A1: TitleApp — 36-Month Projection: Best Case
A2: All figures in USD
B4: M1 | C4: M2 | D4: M3 | E4: M4 | F4: M5 | G4: M6 | H4: M7 | I4: M8 | J4: M9 | K4: M10 | L4: M11 | M4: M12 | N4: M13 | O4: M14 | P4: M15 | Q4: M16 | R4: M17 | S4: M18 | T4: M19 | U4: M20 | V4: M21 | W4: M22 | X4: M23 | Y4: M24 | Z4: M25 | AA4: M26 | AB4: M27 | AC4: M28 | AD4: M29 | AE4: M30 | AF4: M31 | AG4: M32 | AH4: M33 | AI4: M34 | AJ4: M35 | AK4: M36
A5: SUBSCRIBERS
A6: New Subscribers | B6: 10 | C6: 10 | D6: 10 | E6: 25 | F6: 25 | G6: 25 | H6: 50 | I6: 50 | J6: 50 | K6: 80 | L6: 80 | M6: 80 | N6: 120 | O6: 120 | P6: 120 | Q6: 120 | R6: 120 | S6: 120 | T6: 175 | U6: 175 | V6: 175 | W6: 175 | X6: 175 | Y6: 175 | Z6: 250 | AA6: 250 | AB6: 250 | AC6: 250 | AD6: 250 | AE6: 250 | AF6: 250 | AG6: 250 | AH6: 250 | AI6: 250 | AJ6: 250 | AK6: 250
A7: Churned Subscribers | B7: 0 | C7: =-ROUND(B9*Assumptions!$B$29,0) -> -1 | D7: =-ROUND(C9*Assumptions!$B$29,0) -> -1 | E7: =-ROUND(D9*Assumptions!$B$29,0) -> -1 | F7: =-ROUND(E9*Assumptions!$B$29,0) -> -3 | G7: =-ROUND(F9*Assumptions!$B$29,0) -> -4 | H7: =-ROUND(G9*Assumptions!$B$29,0) -> -5 | I7: =-ROUND(H9*Assumptions!$B$29,0) -> -7 | J7: =-ROUND(I9*Assumptions!$B$29,0) -> -9 | ... AK7: =-ROUND(AJ9*Assumptions!$B$29,0) -> -154
A8: Net New Subscribers | B8: =B6+B7 -> 10 | C8: =C6+C7 -> 9 | D8: =D6+D7 -> 9 | E8: =E6+E7 -> 24 | F8: =F6+F7 -> 22 | G8: =G6+G7 -> 21 | H8: =H6+H7 -> 45 | I8: =I6+I7 -> 43 | ... AK8: =AK6+AK7 -> 96
A9: Cumulative Subscribers | B9: =B8 -> 10 | C9: =B9+C8 -> 19 | D9: =C9+D8 -> 28 | E9: =D9+E8 -> 52 | F9: =E9+F8 -> 74 | G9: =F9+G8 -> 95 | H9: =G9+H8 -> 140 | I9: =H9+I8 -> 183 | J9: =I9+J8 -> 224 | ... AK9: =AJ9+AK8 -> 3174
A11: REVENUE
A12: Subscription Revenue | B12: =B9*Assumptions!$B$32 -> 1527.5 | C12: =C9*Assumptions!$B$32 -> 2902.25 | D12: =D9*Assumptions!$B$32 -> 4277 | E12: =E9*Assumptions!$B$32 -> 7943 | F12: =F9*Assumptions!$B$32 -> 11303.5 | G12: =G9*Assumptions!$B$32 -> 14511.25 | H12: =H9*Assumptions!$B$32 -> 21385 | I12: =I9*Assumptions!$B$32 -> 27953.25 | ... AK12: =AK9*Assumptions!$B$32 -> 484828.5
A13: Token/Usage Revenue | B13: =B9*Assumptions!$B$36 -> 80 | C13: =C9*Assumptions!$B$36 -> 152 | D13: =D9*Assumptions!$B$36 -> 224 | E13: =E9*Assumptions!$B$36 -> 416 | F13: =F9*Assumptions!$B$36 -> 592 | G13: =G9*Assumptions!$B$36 -> 760 | H13: =H9*Assumptions!$B$36 -> 1120 | I13: =I9*Assumptions!$B$36 -> 1464 | ... AK13: =AK9*Assumptions!$B$36 -> 25392
A14: Creator Licenses | B14: =ROUND(B9*0.1,0)*Assumptions!$B$37/12 -> 4.0833333 | C14: =ROUND(C9*0.1,0)*Assumptions!$B$37/12 -> 8.1666667 | D14: =ROUND(D9*0.1,0)*Assumptions!$B$37/12 -> 12.25 | E14: =ROUND(E9*0.1,0)*Assumptions!$B$37/12 -> 20.416667 | F14: =ROUND(F9*0.1,0)*Assumptions!$B$37/12 -> 28.583333 | G14: =ROUND(G9*0.1,0)*Assumptions!$B$37/12 -> 40.833333 | H14: =ROUND(H9*0.1,0)*Assumptions!$B$37/12 -> 57.166667 | I14: =ROUND(I9*0.1,0)*Assumptions!$B$37/12 -> 73.5 | ... AK14: =ROUND(AK9*0.1,0)*Assumptions!$B$37/12 -> 1294.4167
A15: Total Monthly Revenue | B15: =B12+B13+B14 -> 1611.5833 | C15: =C12+C13+C14 -> 3062.4167 | D15: =D12+D13+D14 -> 4513.25 | E15: =E12+E13+E14 -> 8379.4167 | F15: =F12+F13+F14 -> 11924.083 | G15: =G12+G13+G14 -> 15312.083 | H15: =H12+H13+H14 -> 22562.167 | I15: =I12+I13+I14 -> 29490.75 | ... AK15: =AK12+AK13+AK14 -> 511514.92
A17: EXPENSES
A18: Monthly Burn (with growth) | B18: =Assumptions!$B$21*(1+Assumptions!$B$46)^0 -> 27800 | C18: =Assumptions!$B$21*(1+Assumptions!$B$46)^0 -> 27800 | D18: =Assumptions!$B$21*(1+Assumptions!$B$46)^0 -> 27800 | E18: =Assumptions!$B$21*(1+Assumptions!$B$46)^1 -> 29190 | F18: =Assumptions!$B$21*(1+Assumptions!$B$46)^1 -> 29190 | G18: =Assumptions!$B$21*(1+Assumptions!$B$46)^1 -> 29190 | H18: =Assumptions!$B$21*(1+Assumptions!$B$46)^2 -> 30649.5 | I18: =Assumptions!$B$21*(1+Assumptions!$B$46)^2 -> 30649.5 | J18: =Assumptions!$B$21*(1+Assumptions!$B$46)^2 -> 30649.5 | K18: =Assumptions!$B$21*(1+Assumptions!$B$46)^3 -> 32181.975 | L18: =Assumptions!$B$21*(1+Assumptions!$B$46)^3 -> 32181.975 | M18: =Assumptions!$B$21*(1+Assumptions!$B$46)^3 -> 32181.975 | N18: =Assumptions!$B$21*(1+Assumptions!$B$46)^4 -> 33791.074 | O18: =Assumptions!$B$21*(1+Assumptions!$B$46)^4 -> 33791.074 | P18: =Assumptions!$B$21*(1+Assumptions!$B$46)^4 -> 33791.074 | Q18: =Assumptions!$B$21*(1+Assumptions!$B$46)^5 -> 35480.627 | R18: =Assumptions!$B$21*(1+Assumptions!$B$46)^5 -> 35480.627 | S18: =Assumptions!$B$21*(1+Assumptions!$B$46)^5 -> 35480.627 | T18: =Assumptions!$B$21*(1+Assumptions!$B$46)^6 -> 37254.659 | U18: =Assumptions!$B$21*(1+Assumptions!$B$46)^6 -> 37254.659 | V18: =Assumptions!$B$21*(1+Assumptions!$B$46)^6 -> 37254.659 | W18: =Assumptions!$B$21*(1+Assumptions!$B$46)^7 -> 39117.392 | X18: =Assumptions!$B$21*(1+Assumptions!$B$46)^7 -> 39117.392 | Y18: =Assumptions!$B$21*(1+Assumptions!$B$46)^7 -> 39117.392 | Z18: =Assumptions!$B$21*(1+Assumptions!$B$46)^8 -> 41073.261 | AA18: =Assumptions!$B$21*(1+Assumptions!$B$46)^8 -> 41073.261 | AB18: =Assumptions!$B$21*(1+Assumptions!$B$46)^8 -> 41073.261 | AC18: =Assumptions!$B$21*(1+Assumptions!$B$46)^9 -> 43126.924 | AD18: =Assumptions!$B$21*(1+Assumptions!$B$46)^9 -> 43126.924 | AE18: =Assumptions!$B$21*(1+Assumptions!$B$46)^9 -> 43126.924 | AF18: =Assumptions!$B$21*(1+Assumptions!$B$46)^10 -> 45283.271 | AG18: =Assumptions!$B$21*(1+Assumptions!$B$46)^10 -> 45283.271 | AH18: =Assumptions!$B$21*(1+Assumptions!$B$46)^10 -> 45283.271 | AI18: =Assumptions!$B$21*(1+Assumptions!$B$46)^11 -> 47547.434 | AJ18: =Assumptions!$B$21*(1+Assumptions!$B$46)^11 -> 47547.434 | AK18: =Assumptions!$B$21*(1+Assumptions!$B$46)^11 -> 47547.434
A19: Variable AI Costs (per sub) | B19: =MAX(0,B9*5-Assumptions!$B$15) -> 0 | C19: =MAX(0,C9*5-Assumptions!$B$15) -> 0 | D19: =MAX(0,D9*5-Assumptions!$B$15) -> 0 | E19: =MAX(0,E9*5-Assumptions!$B$15) -> 0 | F19: =MAX(0,F9*5-Assumptions!$B$15) -> 0 | G19: =MAX(0,G9*5-Assumptions!$B$15) -> 0 | H19: =MAX(0,H9*5-Assumptions!$B$15) -> 0 | I19: =MAX(0,I9*5-Assumptions!$B$15) -> 0 | ... AK19: =MAX(0,AK9*5-Assumptions!$B$15) -> 12870
A20: Total Monthly Expenses | B20: =B18+B19 -> 27800 | C20: =C18+C19 -> 27800 | D20: =D18+D19 -> 27800 | E20: =E18+E19 -> 29190 | F20: =F18+F19 -> 29190 | G20: =G18+G19 -> 29190 | H20: =H18+H19 -> 30649.5 | I20: =I18+I19 -> 30649.5 | ... AK20: =AK18+AK19 -> 60417.434
A22: CASH POSITION
A23: Monthly Net Income | B23: =B15-B20 -> -26188.417 | C23: =C15-C20 -> -24737.583 | D23: =D15-D20 -> -23286.75 | E23: =E15-E20 -> -20810.583 | F23: =F15-F20 -> -17265.917 | G23: =G15-G20 -> -13877.917 | H23: =H15-H20 -> -8087.3333 | I23: =I15-I20 -> -1158.75 | ... AK23: =AK15-AK20 -> 451097.48
A24: Cash Balance | B24: =Assumptions!$B$11+B23 -> 776851.58 | C24: =B24+C23 -> 752114 | D24: =C24+D23 -> 728827.25 | E24: =D24+E23 -> 708016.67 | F24: =E24+F23 -> 690750.75 | G24: =F24+G23 -> 676872.83 | H24: =G24+H23 -> 668785.5 | I24: =H24+I23 -> 667626.75 | J24: =I24+J23 -> 673075.08 | ... AK24: =AJ24+AK23 -> 6578439.8
A25: Cash Positive? | B25: =IF(B23>0,"YES","NO") -> NO | C25: =IF(C23>0,"YES","NO") -> NO | D25: =IF(D23>0,"YES","NO") -> NO | E25: =IF(E23>0,"YES","NO") -> NO | F25: =IF(F23>0,"YES","NO") -> NO | G25: =IF(G23>0,"YES","NO") -> NO | H25: =IF(H23>0,"YES","NO") -> NO | I25: =IF(I23>0,"YES","NO") -> NO | ... AK25: =IF(AK23>0,"YES","NO") -> YES
A27: KEY METRICS
A28: Monthly Recurring Revenue | B28: =B12 -> 1527.5 | C28: =C12 -> 2902.25 | D28: =D12 -> 4277 | E28: =E12 -> 7943 | F28: =F12 -> 11303.5 | G28: =G12 -> 14511.25 | H28: =H12 -> 21385 | I28: =I12 -> 27953.25 | ... AK28: =AK12 -> 484828.5
A29: Annualized Revenue (ARR) | B29: =B15*12 -> 19339 | C29: =C15*12 -> 36749 | D29: =D15*12 -> 54159 | E29: =E15*12 -> 100553 | F29: =F15*12 -> 143089 | G29: =G15*12 -> 183745 | H29: =H15*12 -> 270746 | I29: =I15*12 -> 353889 | ... AK29: =AK15*12 -> 6138179
A30: Burn Multiple | B30: =IF(B15=0,"-",B20/B15) -> 17.250116 | C30: =IF(C15=0,"-",C20/C15) -> 9.077798 | D30: =IF(D15=0,"-",D20/D15) -> 6.1596411 | E30: =IF(E15=0,"-",E20/E15) -> 3.483536 | F30: =IF(F15=0,"-",F20/F15) -> 2.4479869 | G30: =IF(G15=0,"-",G20/G15) -> 1.9063376 | H30: =IF(H15=0,"-",H20/H15) -> 1.3584467 | I30: =IF(I15=0,"-",I20/I15) -> 1.039292 | ... AK30: =IF(AK15=0,"-",AK20/AK15) -> 0.11811471
A31: Months of Cash Remaining | B31: =IF(B23>=0,"∞",B24/(-B23)) -> 29.663939 | C31: =IF(C23>=0,"∞",C24/(-C23)) -> 30.403697 | D31: =IF(D23>=0,"∞",D24/(-D23)) -> 31.297938 | E31: =IF(E23>=0,"∞",E24/(-E23)) -> 34.021952 | F31: =IF(F23>=0,"∞",F24/(-F23)) -> 40.006607 | G31: =IF(G23>=0,"∞",G24/(-G23)) -> 48.773375 | H31: =IF(H23>=0,"∞",H24/(-H23)) -> 82.695429 | I31: =IF(I23>=0,"∞",I24/(-I23)) -> 576.16117 | ... AK31: =IF(AK23>=0,"∞",AK24/(-AK23)) -> ∞

Sheet Summary
A1: TitleApp — Scenario Comparison Summary
A3: Metric | B3: No Revenue | C3: Base Case | D3: Best Case
A4: Net Proceeds from Raise | B4: =Assumptions!B11 -> 803040 | C4: =Assumptions!B11 -> 803040 | D4: =Assumptions!B11 -> 803040
A5: Monthly Burn (starting) | B5: =Assumptions!B21 -> 27800 | C5: =Assumptions!B21 -> 27800 | D5: =Assumptions!B21 -> 27800
A6: Zero-Revenue Runway (months) | B6: =Assumptions!B22 -> 29 | C6: =Assumptions!B22 -> 29 | D6: =Assumptions!B22 -> 29
B7: ='No Revenue'!M9 -> 0 | C7: ='Base Case'!M9 -> 177 | D7: ='Best Case'!M9 -> 420
A8: Month 12 Subscribers | B8: ='No Revenue'!M9 -> 0 | C8: ='Base Case'!M9 -> 177 | D8: ='Best Case'!M9 -> 420
A9: Month 24 Subscribers | B9: ='No Revenue'!Y9 -> 0 | C9: ='Base Case'!Y9 -> 687 | D9: ='Best Case'!Y9 -> 1622
A10: Month 36 Subscribers | B10: ='No Revenue'!AK9 -> 0 | C10: ='Base Case'!AK9 -> 1289 | D10: ='Best Case'!AK9 -> 3174
B11: ='No Revenue'!M12 -> 0 | C11: ='Base Case'!M12 -> 27036.75 | D11: ='Best Case'!M12 -> 64155
A12: Month 12 MRR | B12: ='No Revenue'!M12 -> 0 | C12: ='Base Case'!M12 -> 27036.75 | D12: ='Best Case'!M12 -> 64155
A13: Month 24 MRR | B13: ='No Revenue'!Y12 -> 0 | C13: ='Base Case'!Y12 -> 104939.25 | D13: ='Best Case'!Y12 -> 247760.5
A14: Month 36 MRR | B14: ='No Revenue'!AK12 -> 0 | C14: ='Base Case'!AK12 -> 196894.75 | D14: ='Best Case'!AK12 -> 484828.5
B15: ='No Revenue'!M29 -> 0 | C15: ='Base Case'!M29 -> 342315 | D15: ='Best Case'!M29 -> 812238
A16: Month 12 ARR | B16: ='No Revenue'!M29 -> 0 | C16: ='Base Case'!M29 -> 342315 | D16: ='Best Case'!M29 -> 812238
A17: Month 24 ARR | B17: ='No Revenue'!Y29 -> 0 | C17: ='Base Case'!Y29 -> 1328604 | D17: ='Best Case'!Y29 -> 3136776
A18: Month 36 ARR | B18: ='No Revenue'!AK29 -> 0 | C18: ='Base Case'!AK29 -> 2492802 | D18: ='Best Case'!AK29 -> 6138179
B19: ='No Revenue'!M24 -> 443575.58 | C19: ='Base Case'!M24 -> 571859.24 | D19: ='Best Case'!M24 -> 749129.32
A20: Month 12 Cash Balance | B20: ='No Revenue'!M24 -> 443575.58 | C20: ='Base Case'!M24 -> 571859.24 | D20: ='Best Case'!M24 -> 749129.32
A21: Month 24 Cash Balance | B21: ='No Revenue'!Y24 -> 6644.3198 | C21: ='Base Case'!Y24 -> 986800.57 | D21: ='Best Case'!Y24 -> 2311326.3
A22: Month 36 Cash Balance | B22: ='No Revenue'!AK24 -> -524448.35 | C22: ='Base Case'!AK24 -> 2447584.9 | D22: ='Best Case'!AK24 -> 6578439.8
B23: N/A | C23: =IFERROR(MATCH("YES",'Base Case'!B25:AK25,0),"Not in 36mo") -> 13 | D23: =IFERROR(MATCH("YES",'Best Case'!B25:AK25,0),"Not in 36mo") -> 9
A24: Cash Positive Month | B24: N/A | C24: =IFERROR(MATCH("YES",'Base Case'!B25:AK25,0),"Not in 36mo") -> 13 | D24: =IFERROR(MATCH("YES",'Best Case'!B25:AK25,0),"Not in 36mo") -> 9
A27: Key Takeaways
A28: No Revenue: Cash runs out in ~28 months. This is the baseline safety net.
A29: Base Case: Modest growth gets to cash-flow positive mid-2027. $1.07M raise provides comfortable runway.
A30: Best Case: Aggressive growth — 52-worker catalog drives bundle sales. Cash positive by early 2027.
A31: The 52-worker construction/development vertical is the accelerant. Bundle pricing ($630-$3,200/mo) dramatically increases ARPU.
